Workbook

Sheet README
A1: SALES PERFORMANCE & PROFITABILITY ANALYSIS
A2: Portfolio project | Simulated Ghanaian retail business | Microsoft Excel
A3: Purpose | B3: Demonstrate data cleaning, KPI calculation, PivotTable-style summaries, dashboarding, and business recommendations.
A4: Important note | B4: All records are simulated for learning and portfolio demonstration. This is not real company data.
A5: Workbook guide | B5: Raw Data: simulated transactions including deliberate data quality issues.
B6: Clean Data: corrected data and formula-driven KPIs.
B7: Monthly Analysis: monthly sales, estimated contribution, and order count.
B8: Category Analysis: sales and estimated contribution by product category.
B9: Region Analysis: sales and estimated contribution by region.
B10: Dashboard: management-facing KPIs and charts.
B11: Methodology: KPI definitions, assumptions and limitations.
A12: Suggested workflow | B12: 1. Review Raw Data. 2. Check Clean Data decisions. 3. Inspect KPI formulas. 4. Review analysis tabs. 5. Read dashboard and recommendations.
A13: Definitions | B13: Net Sales = Quantity × Unit Price × (1 − Discount Rate).
B14: Product Cost = Quantity × Unit Cost.
B15: Estimated Contribution = Net Sales − Product Cost − Delivery Cost.
B16: Contribution Margin = Estimated Contribution ÷ Net Sales.
A17: Limitations | B17: No overheads, taxes, returns, inventory holding costs, marketing costs, or payment fees are included. Contribution is not accounting profit.
A18: Interview tip | B18: Be ready to explain how you cleaned data, why you chose each KPI, what the dashboard suggests, and what further data management should collect.

Sheet Dashboard
A1: SALES PERFORMANCE DASHBOARD | SIMULATED DATA
A2: Reporting period: Jan–Dec 2025 | Currency: GHS | Estimated contribution excludes overheads and other unrecorded costs
A3: Total Net Sales (GHS) | B3: Estimated Contribution (GHS) | C3: Contribution Margin | D3: Transactions | E3: Units Sold
A4: ='Monthly Analysis'!B2+'Monthly Analysis'!B3+'Monthly Analysis'!B4+'Monthly Analysis'!B5+'Monthly Analysis'!B6+'Monthly Analysis'!B7+'Monthly Analysis'!B8+'Monthly Analysis'!B9+'Monthly Analysis'!B10+'Monthly Analysis'!B11+'Monthly Analysis'!B12+'Monthly Analysis'!B13 | B4: ='Monthly Analysis'!C2+'Monthly Analysis'!C3+'Monthly Analysis'!C4+'Monthly Analysis'!C5+'Monthly Analysis'!C6+'Monthly Analysis'!C7+'Monthly Analysis'!C8+'Monthly Analysis'!C9+'Monthly Analysis'!C10+'Monthly Analysis'!C11+'Monthly Analysis'!C12+'Monthly Analysis'!C13 | C4: =IFERROR(B4/A4,0) | D4: =SUM('Monthly Analysis'!D2:D13) | E4: =SUM('Clean Data'!H2:H1201)
A5: Use the analysis tabs to investigate trends and compare product categories and regions.

Sheet Raw Data
A1: Order ID | B1: Order Date | C1: Product Category | D1: Product | E1: Region | F1: Sales Channel | G1: Customer Type | H1: Quantity | I1: Unit Price (GHS) | J1: Unit Cost (GHS) | K1: Discount Rate | L1: Delivery Cost (GHS)
A2: ORD-10001 | B2: 45769 | C2: Clothing | D2: Dresses | E2: Ashanti | F2: Online | G2: Returning | H2: 4 | I2: 150 | J2: 84.76 | K2: 0 | L2: 8.12
A3: ORD-10002 | B3: 45899 | C3: Clothing | D3: Trousers | E3: Greater Accra | F3: Retail Shop | G3: Returning | H3: 1 | I3: 130 | J3: 73.8 | K3: 0 | L3: 3.84
A4: ORD-10003 | B4: 45801 | C4: Home & Lifestyle | D4: Small Home Goods | E4: Ashanti | F4: Retail Shop | G4: Returning | H4: 4 | I4: 130 | J4: 70.56 | K4: 0 | L4: 10.95
A5: ORD-10004 | B5: 45971 | C5: Accessories | D5: Watches | E5: Northern | F5: Phone/WhatsApp | G5: New | H5: 3 | I5: 80 | J5: 37.41 | K5: 0.05 | L5: 22.63
A6: ORD-10005 | B6: 45898 | C6: Home & Lifestyle | D6: Travel Mugs | E6: Greater Accra | F6: Retail Shop | G6: Returning | H6: 2 | I6: 90 | J6: 46.61 | K6: 0 | L6: 9.33
A7: ORD-10006 | B7: 45936 | C7: Clothing | D7: Trousers | E7: Ashanti | F7: Phone/WhatsApp | G7: Returning | H7: 3 | I7: 110 | J7: 55.82 | K7: 0.05 | L7: 37.45
A8: ORD-10007 | B8: 45689 | C8: Home & Lifestyle | D8: Backpacks | E8: Greater Accra | F8: Retail Shop | G8: Returning | H8: 2 | I8: 200 | J8: 103.12 | K8: 0 | L8: 8.8
A9: ORD-10008 | B9: 45982 | C9: Clothing | D9: Dresses | E9: Ashanti | F9: Phone/WhatsApp | G9: Returning | H9: 3 | I9: 230 | J9: 122.39 | K9: 0.15 | L9: 30.18
A10: ORD-10009 | B10: 45697 | C10: Accessories | D10: Bags | E10: Ashanti | F10: Retail Shop | G10: Returning | H10: 3 | I10: 85 | J10: 37.84 | K10: 0 | L10: 9.33
A11: ORD-10010 | B11: 45665 | C11: Clothing | D11: Dresses | E11: Ashanti | F11: Retail Shop | G11: Returning | H11: 1 | I11: 135 | J11: 67.51 | K11: 0.05 | L11: 8.18
A12: ORD-10011 | B12: 45896 | C12: Footwear | D12: Boots | E12: Greater Accra | F12: Retail Shop | G12: Returning | H12: 1 | I12: 420 | J12: 252.42 | K12: 0 | L12: 3.68
A13: ORD-10012 | B13: 45675 | C13: Accessories | D13: Belts | E13: Greater Accra | F13: Online | G13: Returning | H13: 4 | I13: 180 | J13: 77.34 | K13: 0 | L13: 30.41
... A32: ORD-10031 | B32: 45799 | C32: Clothing | D32: Jackets | E32: Ashanti | F32: Phone/WhatsApp | G32: Returning | H32: 1 | I32: 180 | J32: 82.76 | K32: 0.1 | L32: 35.45
A33: ORD-10032 | B33: 45714 | C33: Home & Lifestyle | D33: Small Home Goods | F33: Retail Shop | G33: Returning | H33: 1 | I33: 140 | J33: 82.92 | K33: 0.1 | L33: 3
A34: ORD-10033 | B34: 45941 | C34: Clothing | D34: Trousers | E34: Greater Accra | F34: Retail Shop | G34: New | H34: 1 | I34: 135 | J34: 65.36 | K34: 0 | L34: 8.12
A35: ORD-10034 | B35: 45892 | C35: Clothing | D35: Shirts | E35: Greater Accra | F35: Online | G35: New | H35: 1 | I35: 170 | J35: 91.26 | K35: 0.05 | L35: 14.27
A36: ORD-10035 | B36: 45997 | C36: Footwear | D36: Boots | E36: Greater Accra | F36: Retail Shop | G36: New | H36: 1 | I36: 230 | J36: 144.68 | K36: 0.1 | L36: 3.79
A37: ORD-10036 | B37: 45964 | C37: Footwear | D37: Boots | E37: Western | F37: Phone/WhatsApp | G37: New | H37: 8 | I37: 225 | J37: 117.98 | K37: 0.05 | L37: 28.51
A38: ORD-10037 | B38: 45707 | C38: Home & Lifestyle | D38: Wallets | E38: Central | F38: Online | G38: New | H38: 1 | I38: 105 | J38: 59.06 | K38: 0.2 | L38: 16.89
A39: ORD-10038 | B39: 45718 | C39: Home & Lifestyle | D39: Backpacks | E39: Ashanti | F39: Retail Shop | G39: New | H39: 2 | I39: 135 | J39: 72.5 | K39: 0.05 | L39: 0.04
A40: ORD-10039 | B40: 45666 | C40: Clothing | D40: Jackets | E40: Greater Accra | F40: Retail Shop | G40: Returning | H40: 3 | I40: 130 | J40: 71.81 | K40: 0.05 | L40: 3.78
A41: ORD-10040 | B41: 45941 | C41: Home & Lifestyle | D41: Travel Mugs | E41: Ashanti | F41: Retail Shop | G41: Returning | H41: 1 | I41: 135 | J41: 77.9 | K41: 0 | L41: 9.7
A42: ORD-10041 | B42: 45721 | C42: Clothing | D42: Trousers | E42: Greater Accra | F42: Online | G42: New | H42: 2 | I42: 160 | J42: 89.13 | K42: 0 | L42: 21.56
A43: ORD-10042 | B43: 45684 | C43: Footwear | D43: Sandals | E43: Greater Accra | F43: Online | G43: Returning | H43: 2 | I43: 245 | J43: 154.54 | K43: 0 | L43: 21.15
A44: ORD-10043 | B44: 45749 | C44: Home & Lifestyle | D44: Backpacks | E44: Western | F44: Online | G44: Returning | H44: 4 | I44: 110 | J44: 56.75 | K44: 0 | L44: 36.5
A45: ORD-10044 | B45: 45768 | C45: Accessories | D45: Belts | E45: Greater Accra | F45: Retail Shop | G45: Returning | H45: 1 | I45: 115 | J45: 57.81 | K45: 0 | L45: 11.3
... A288: ORD-10287 | B288: 45742 | C288: Clothing | D288: Dresses | E288: Greater Accra | F288: Online | G288: Returning | H288: 2 | I288: 180 | J288: 89.54 | K288: 0 | L288: 12.1
A289: ORD-10288 | B289: 45945 | C289: Accessories | D289: Sunglasses | F289: Retail Shop | G289: New | H289: 1 | I289: 85 | J289: 39.05 | K289: 0 | L289: 4.76
A290: ORD-10289 | B290: 45750 | C290: Accessories | D290: Sunglasses | E290: Western | F290: Retail Shop | G290: Returning | H290: 4 | I290: 105 | J290: 52.12 | K290: 0 | L290: 8.45
A291: ORD-10290 | B291: 45981 | C291: Clothing | D291: Dresses | E291: Western | F291: Online | G291: Returning | H291: 2 | I291: 155 | J291: 83.96 | K291: 0 | L291: 25.89
A292: ORD-10291 | B292: 45892 | C292: Clothing | D292: Trousers | E292: Ashanti | F292: Retail Shop | G292: Returning | H292: 3 | I292: 110 | J292: 63.95 | K292: 0 | L292: 6.39
A293: ORD-10292 | B293: 45898 | C293: Clothing | D293: Jackets | E293: Northern | F293: Phone/WhatsApp | G293: New | H293: 1 | I293: 170 | J293: 92.68 | K293: 0 | L293: 33.69
A294: ORD-10293 | B294: 45719 | C294: Footwear | D294: Formal Shoes | E294: Western | F294: Online | G294: Returning | H294: 2 | I294: 275 | J294: 154.83 | K294: 0.05 | L294: 9.31
A295: ORD-10294 | B295: 45926 | C295: Footwear | D295: Formal Shoes | E295: Western | F295: Online | G295: Returning | H295: 1 | I295: 265 | J295: 148.94 | K295: 0.1 | L295: 21.46
A296: ORD-10295 | B296: 45776 | C296: Footwear | D296: Formal Shoes | E296: Greater Accra | F296: Retail Shop | G296: New | H296: 1 | I296: 340 | J296: 189.18 | K296: 0 | L296: 0.17
A297: ORD-10296 | B297: 45924 | C297: Accessories | D297: Bags | E297: Greater Accra | F297: Phone/WhatsApp | G297: Returning | H297: 2 | I297: 125 | J297: 65.6 | K297: 0 | L297: 12.83
A298: ORD-10297 | B298: 45756 | C298: Accessories | D298: Sunglasses | E298: Ashanti | F298: Online | G298: Returning | H298: 3 | I298: 140 | J298: 60.73 | K298: 0.05 | L298: 26.9
A299: ORD-10298 | B299: 45815 | C299: Clothing | D299: Trousers | E299: Greater Accra | F299: Phone/WhatsApp | G299: Returning | H299: 5 | I299: 160 | J299: 92.69 | K299: 0.1 | L299: 25.86
A300: ORD-10299 | B300: 45864 | C300: Home & Lifestyle | D300: Travel Mugs | E300: Greater Accra | F300: Online | G300: Returning | H300: 1 | I300: 85 | J300: 45.17 | K300: 0.2 | L300: 39.64
...

Sheet Clean Data
A1: Order ID | B1: Order Date | C1: Product Category | D1: Product | E1: Region | F1: Sales Channel | G1: Customer Type | H1: Quantity | I1: Unit Price (GHS) | J1: Unit Cost (GHS) | K1: Discount Rate | L1: Delivery Cost (GHS) | M1: Net Sales (GHS) | N1: Product Cost (GHS) | O1: Estimated Contribution (GHS) | P1: Contribution Margin | Q1: Data Quality Note
A2: ORD-10001 | B2: 45769 | C2: Clothing | D2: Dresses | E2: Ashanti | F2: Online | G2: Returning | H2: 4 | I2: 150 | J2: 84.76 | K2: 0 | L2: 8.12 | M2: =H2*I2*(1-K2) | N2: =H2*J2 | O2: =M2-N2-L2 | P2: =IFERROR(O2/M2,0) | Q2: =IF(H2<=0,"Review: quantity <= 0",IF(K2>0.3,"Review: discount > 30%",IF(G2="","Review: missing customer type","OK")))
A3: ORD-10002 | B3: 45899 | C3: Clothing | D3: Trousers | E3: Greater Accra | F3: Retail Shop | G3: Returning | H3: 1 | I3: 130 | J3: 73.8 | K3: 0 | L3: 3.84 | M3: =H3*I3*(1-K3) | N3: =H3*J3 | O3: =M3-N3-L3 | P3: =IFERROR(O3/M3,0) | Q3: =IF(H3<=0,"Review: quantity <= 0",IF(K3>0.3,"Review: discount > 30%",IF(G3="","Review: missing customer type","OK")))
A4: ORD-10003 | B4: 45801 | C4: Home & Lifestyle | D4: Small Home Goods | E4: Ashanti | F4: Retail Shop | G4: Returning | H4: 4 | I4: 130 | J4: 70.56 | K4: 0 | L4: 10.95 | M4: =H4*I4*(1-K4) | N4: =H4*J4 | O4: =M4-N4-L4 | P4: =IFERROR(O4/M4,0) | Q4: =IF(H4<=0,"Review: quantity <= 0",IF(K4>0.3,"Review: discount > 30%",IF(G4="","Review: missing customer type","OK")))
A5: ORD-10004 | B5: 45971 | C5: Accessories | D5: Watches | E5: Northern | F5: Phone/WhatsApp | G5: New | H5: 3 | I5: 80 | J5: 37.41 | K5: 0.05 | L5: 22.63 | M5: =H5*I5*(1-K5) | N5: =H5*J5 | O5: =M5-N5-L5 | P5: =IFERROR(O5/M5,0) | Q5: =IF(H5<=0,"Review: quantity <= 0",IF(K5>0.3,"Review: discount > 30%",IF(G5="","Review: missing customer type","OK")))
A6: ORD-10005 | B6: 45898 | C6: Home & Lifestyle | D6: Travel Mugs | E6: Greater Accra | F6: Retail Shop | G6: Returning | H6: 2 | I6: 90 | J6: 46.61 | K6: 0 | L6: 9.33 | M6: =H6*I6*(1-K6) | N6: =H6*J6 | O6: =M6-N6-L6 | P6: =IFERROR(O6/M6,0) | Q6: =IF(H6<=0,"Review: quantity <= 0",IF(K6>0.3,"Review: discount > 30%",IF(G6="","Review: missing customer type","OK")))
A7: ORD-10006 | B7: 45936 | C7: Clothing | D7: Trousers | E7: Ashanti | F7: Phone/WhatsApp | G7: Returning | H7: 3 | I7: 110 | J7: 55.82 | K7: 0.05 | L7: 37.45 | M7: =H7*I7*(1-K7) | N7: =H7*J7 | O7: =M7-N7-L7 | P7: =IFERROR(O7/M7,0) | Q7: =IF(H7<=0,"Review: quantity <= 0",IF(K7>0.3,"Review: discount > 30%",IF(G7="","Review: missing customer type","OK")))
A8: ORD-10007 | B8: 45689 | C8: Home & Lifestyle | D8: Backpacks | E8: Greater Accra | F8: Retail Shop | G8: Returning | H8: 2 | I8: 200 | J8: 103.12 | K8: 0 | L8: 8.8 | M8: =H8*I8*(1-K8) | N8: =H8*J8 | O8: =M8-N8-L8 | P8: =IFERROR(O8/M8,0) | Q8: =IF(H8<=0,"Review: quantity <= 0",IF(K8>0.3,"Review: discount > 30%",IF(G8="","Review: missing customer type","OK")))
A9: ORD-10008 | B9: 45982 | C9: Clothing | D9: Dresses | E9: Ashanti | F9: Phone/WhatsApp | G9: Returning | H9: 3 | I9: 230 | J9: 122.39 | K9: 0.15 | L9: 30.18 | M9: =H9*I9*(1-K9) | N9: =H9*J9 | O9: =M9-N9-L9 | P9: =IFERROR(O9/M9,0) | Q9: =IF(H9<=0,"Review: quantity <= 0",IF(K9>0.3,"Review: discount > 30%",IF(G9="","Review: missing customer type","OK")))
A10: ORD-10009 | B10: 45697 | C10: Accessories | D10: Bags | E10: Ashanti | F10: Retail Shop | G10: Returning | H10: 3 | I10: 85 | J10: 37.84 | K10: 0 | L10: 9.33 | M10: =H10*I10*(1-K10) | N10: =H10*J10 | O10: =M10-N10-L10 | P10: =IFERROR(O10/M10,0) | Q10: =IF(H10<=0,"Review: quantity <= 0",IF(K10>0.3,"Review: discount > 30%",IF(G10="","Review: missing customer type","OK")))
A11: ORD-10010 | B11: 45665 | C11: Clothing | D11: Dresses | E11: Ashanti | F11: Retail Shop | G11: Returning | H11: 1 | I11: 135 | J11: 67.51 | K11: 0.05 | L11: 8.18 | M11: =H11*I11*(1-K11) | N11: =H11*J11 | O11: =M11-N11-L11 | P11: =IFERROR(O11/M11,0) | Q11: =IF(H11<=0,"Review: quantity <= 0",IF(K11>0.3,"Review: discount > 30%",IF(G11="","Review: missing customer type","OK")))
A12: ORD-10011 | B12: 45896 | C12: Footwear | D12: Boots | E12: Greater Accra | F12: Retail Shop | G12: Returning | H12: 1 | I12: 420 | J12: 252.42 | K12: 0 | L12: 3.68 | M12: =H12*I12*(1-K12) | N12: =H12*J12 | O12: =M12-N12-L12 | P12: =IFERROR(O12/M12,0) | Q12: =IF(H12<=0,"Review: quantity <= 0",IF(K12>0.3,"Review: discount > 30%",IF(G12="","Review: missing customer type","OK")))
A13: ORD-10012 | B13: 45675 | C13: Accessories | D13: Belts | E13: Greater Accra | F13: Online | G13: Returning | H13: 4 | I13: 180 | J13: 77.34 | K13: 0 | L13: 30.41 | M13: =H13*I13*(1-K13) | N13: =H13*J13 | O13: =M13-N13-L13 | P13: =IFERROR(O13/M13,0) | Q13: =IF(H13<=0,"Review: quantity <= 0",IF(K13>0.3,"Review: discount > 30%",IF(G13="","Review: missing customer type","OK")))
... A1201: ORD-11200 | B1201: 45673 | C1201: Footwear | D1201: Boots | E1201: Ashanti | F1201: Online | G1201: Returning | H1201: 1 | I1201: 260 | J1201: 142.69 | K1201: 0 | L1201: 28.81 | M1201: =H1201*I1201*(1-K1201) | N1201: =H1201*J1201 | O1201: =M1201-N1201-L1201 | P1201: =IFERROR(O1201/M1201,0) | Q1201: =IF(H1201<=0,"Review: quantity <= 0",IF(K1201>0.3,"Review: discount > 30%",IF(G1201="","Review: missing customer type","OK")))

Sheet Monthly Analysis
A1: Month | B1: Net Sales (GHS) | C1: Estimated Contribution (GHS) | D1: Orders | E1: Contribution Margin
A2: 45658 | B2: =SUMIFS('Clean Data'!$M:$M,'Clean Data'!$B:$B,">="&A2,'Clean Data'!$B:$B,"<"&EDATE(A2,1)) | C2: =SUMIFS('Clean Data'!$O:$O,'Clean Data'!$B:$B,">="&A2,'Clean Data'!$B:$B,"<"&EDATE(A2,1)) | D2: =COUNTIFS('Clean Data'!$B:$B,">="&A2,'Clean Data'!$B:$B,"<"&EDATE(A2,1)) | E2: =IFERROR(C2/B2,0)
A3: 45689 | B3: =SUMIFS('Clean Data'!$M:$M,'Clean Data'!$B:$B,">="&A3,'Clean Data'!$B:$B,"<"&EDATE(A3,1)) | C3: =SUMIFS('Clean Data'!$O:$O,'Clean Data'!$B:$B,">="&A3,'Clean Data'!$B:$B,"<"&EDATE(A3,1)) | D3: =COUNTIFS('Clean Data'!$B:$B,">="&A3,'Clean Data'!$B:$B,"<"&EDATE(A3,1)) | E3: =IFERROR(C3/B3,0)
A4: 45717 | B4: =SUMIFS('Clean Data'!$M:$M,'Clean Data'!$B:$B,">="&A4,'Clean Data'!$B:$B,"<"&EDATE(A4,1)) | C4: =SUMIFS('Clean Data'!$O:$O,'Clean Data'!$B:$B,">="&A4,'Clean Data'!$B:$B,"<"&EDATE(A4,1)) | D4: =COUNTIFS('Clean Data'!$B:$B,">="&A4,'Clean Data'!$B:$B,"<"&EDATE(A4,1)) | E4: =IFERROR(C4/B4,0)
A5: 45748 | B5: =SUMIFS('Clean Data'!$M:$M,'Clean Data'!$B:$B,">="&A5,'Clean Data'!$B:$B,"<"&EDATE(A5,1)) | C5: =SUMIFS('Clean Data'!$O:$O,'Clean Data'!$B:$B,">="&A5,'Clean Data'!$B:$B,"<"&EDATE(A5,1)) | D5: =COUNTIFS('Clean Data'!$B:$B,">="&A5,'Clean Data'!$B:$B,"<"&EDATE(A5,1)) | E5: =IFERROR(C5/B5,0)
A6: 45778 | B6: =SUMIFS('Clean Data'!$M:$M,'Clean Data'!$B:$B,">="&A6,'Clean Data'!$B:$B,"<"&EDATE(A6,1)) | C6: =SUMIFS('Clean Data'!$O:$O,'Clean Data'!$B:$B,">="&A6,'Clean Data'!$B:$B,"<"&EDATE(A6,1)) | D6: =COUNTIFS('Clean Data'!$B:$B,">="&A6,'Clean Data'!$B:$B,"<"&EDATE(A6,1)) | E6: =IFERROR(C6/B6,0)
A7: 45809 | B7: =SUMIFS('Clean Data'!$M:$M,'Clean Data'!$B:$B,">="&A7,'Clean Data'!$B:$B,"<"&EDATE(A7,1)) | C7: =SUMIFS('Clean Data'!$O:$O,'Clean Data'!$B:$B,">="&A7,'Clean Data'!$B:$B,"<"&EDATE(A7,1)) | D7: =COUNTIFS('Clean Data'!$B:$B,">="&A7,'Clean Data'!$B:$B,"<"&EDATE(A7,1)) | E7: =IFERROR(C7/B7,0)
A8: 45839 | B8: =SUMIFS('Clean Data'!$M:$M,'Clean Data'!$B:$B,">="&A8,'Clean Data'!$B:$B,"<"&EDATE(A8,1)) | C8: =SUMIFS('Clean Data'!$O:$O,'Clean Data'!$B:$B,">="&A8,'Clean Data'!$B:$B,"<"&EDATE(A8,1)) | D8: =COUNTIFS('Clean Data'!$B:$B,">="&A8,'Clean Data'!$B:$B,"<"&EDATE(A8,1)) | E8: =IFERROR(C8/B8,0)
A9: 45870 | B9: =SUMIFS('Clean Data'!$M:$M,'Clean Data'!$B:$B,">="&A9,'Clean Data'!$B:$B,"<"&EDATE(A9,1)) | C9: =SUMIFS('Clean Data'!$O:$O,'Clean Data'!$B:$B,">="&A9,'Clean Data'!$B:$B,"<"&EDATE(A9,1)) | D9: =COUNTIFS('Clean Data'!$B:$B,">="&A9,'Clean Data'!$B:$B,"<"&EDATE(A9,1)) | E9: =IFERROR(C9/B9,0)
A10: 45901 | B10: =SUMIFS('Clean Data'!$M:$M,'Clean Data'!$B:$B,">="&A10,'Clean Data'!$B:$B,"<"&EDATE(A10,1)) | C10: =SUMIFS('Clean Data'!$O:$O,'Clean Data'!$B:$B,">="&A10,'Clean Data'!$B:$B,"<"&EDATE(A10,1)) | D10: =COUNTIFS('Clean Data'!$B:$B,">="&A10,'Clean Data'!$B:$B,"<"&EDATE(A10,1)) | E10: =IFERROR(C10/B10,0)
A11: 45931 | B11: =SUMIFS('Clean Data'!$M:$M,'Clean Data'!$B:$B,">="&A11,'Clean Data'!$B:$B,"<"&EDATE(A11,1)) | C11: =SUMIFS('Clean Data'!$O:$O,'Clean Data'!$B:$B,">="&A11,'Clean Data'!$B:$B,"<"&EDATE(A11,1)) | D11: =COUNTIFS('Clean Data'!$B:$B,">="&A11,'Clean Data'!$B:$B,"<"&EDATE(A11,1)) | E11: =IFERROR(C11/B11,0)
A12: 45962 | B12: =SUMIFS('Clean Data'!$M:$M,'Clean Data'!$B:$B,">="&A12,'Clean Data'!$B:$B,"<"&EDATE(A12,1)) | C12: =SUMIFS('Clean Data'!$O:$O,'Clean Data'!$B:$B,">="&A12,'Clean Data'!$B:$B,"<"&EDATE(A12,1)) | D12: =COUNTIFS('Clean Data'!$B:$B,">="&A12,'Clean Data'!$B:$B,"<"&EDATE(A12,1)) | E12: =IFERROR(C12/B12,0)
A13: 45992 | B13: =SUMIFS('Clean Data'!$M:$M,'Clean Data'!$B:$B,">="&A13,'Clean Data'!$B:$B,"<"&EDATE(A13,1)) | C13: =SUMIFS('Clean Data'!$O:$O,'Clean Data'!$B:$B,">="&A13,'Clean Data'!$B:$B,"<"&EDATE(A13,1)) | D13: =COUNTIFS('Clean Data'!$B:$B,">="&A13,'Clean Data'!$B:$B,"<"&EDATE(A13,1)) | E13: =IFERROR(C13/B13,0)

Sheet Category Analysis
A1: Product Category | B1: Net Sales (GHS) | C1: Estimated Contribution (GHS) | D1: Units Sold | E1: Contribution Margin
A2: Footwear | B2: =SUMIF('Clean Data'!$C:$C,A2,'Clean Data'!$M:$M) | C2: =SUMIF('Clean Data'!$C:$C,A2,'Clean Data'!$O:$O) | D2: =SUMIF('Clean Data'!$C:$C,A2,'Clean Data'!$H:$H) | E2: =IFERROR(C2/B2,0)
A3: Clothing | B3: =SUMIF('Clean Data'!$C:$C,A3,'Clean Data'!$M:$M) | C3: =SUMIF('Clean Data'!$C:$C,A3,'Clean Data'!$O:$O) | D3: =SUMIF('Clean Data'!$C:$C,A3,'Clean Data'!$H:$H) | E3: =IFERROR(C3/B3,0)
A4: Accessories | B4: =SUMIF('Clean Data'!$C:$C,A4,'Clean Data'!$M:$M) | C4: =SUMIF('Clean Data'!$C:$C,A4,'Clean Data'!$O:$O) | D4: =SUMIF('Clean Data'!$C:$C,A4,'Clean Data'!$H:$H) | E4: =IFERROR(C4/B4,0)
A5: Home & Lifestyle | B5: =SUMIF('Clean Data'!$C:$C,A5,'Clean Data'!$M:$M) | C5: =SUMIF('Clean Data'!$C:$C,A5,'Clean Data'!$O:$O) | D5: =SUMIF('Clean Data'!$C:$C,A5,'Clean Data'!$H:$H) | E5: =IFERROR(C5/B5,0)

Sheet Region Analysis
A1: Region | B1: Net Sales (GHS) | C1: Estimated Contribution (GHS) | D1: Orders | E1: Contribution Margin
A2: Greater Accra | B2: =SUMIF('Clean Data'!$E:$E,A2,'Clean Data'!$M:$M) | C2: =SUMIF('Clean Data'!$E:$E,A2,'Clean Data'!$O:$O) | D2: =COUNTIF('Clean Data'!$E:$E,A2) | E2: =IFERROR(C2/B2,0)
A3: Ashanti | B3: =SUMIF('Clean Data'!$E:$E,A3,'Clean Data'!$M:$M) | C3: =SUMIF('Clean Data'!$E:$E,A3,'Clean Data'!$O:$O) | D3: =COUNTIF('Clean Data'!$E:$E,A3) | E3: =IFERROR(C3/B3,0)
A4: Western | B4: =SUMIF('Clean Data'!$E:$E,A4,'Clean Data'!$M:$M) | C4: =SUMIF('Clean Data'!$E:$E,A4,'Clean Data'!$O:$O) | D4: =COUNTIF('Clean Data'!$E:$E,A4) | E4: =IFERROR(C4/B4,0)
A5: Central | B5: =SUMIF('Clean Data'!$E:$E,A5,'Clean Data'!$M:$M) | C5: =SUMIF('Clean Data'!$E:$E,A5,'Clean Data'!$O:$O) | D5: =COUNTIF('Clean Data'!$E:$E,A5) | E5: =IFERROR(C5/B5,0)
A6: Northern | B6: =SUMIF('Clean Data'!$E:$E,A6,'Clean Data'!$M:$M) | C6: =SUMIF('Clean Data'!$E:$E,A6,'Clean Data'!$O:$O) | D6: =COUNTIF('Clean Data'!$E:$E,A6) | E6: =IFERROR(C6/B6,0)
A7: Unknown | B7: =SUMIF('Clean Data'!$E:$E,A7,'Clean Data'!$M:$M) | C7: =SUMIF('Clean Data'!$E:$E,A7,'Clean Data'!$O:$O) | D7: =COUNTIF('Clean Data'!$E:$E,A7) | E7: =IFERROR(C7/B7,0)

Sheet Methodology
A1: METHODOLOGY, KPI DEFINITIONS & LIMITATIONS
A2: Metric | B2: Definition / formula | C2: Interpretation
A3: Net Sales | B3: Quantity × Unit Price × (1 − Discount Rate) | C3: Sales after recorded discounts; excludes returns and taxes unless represented in data.
A4: Product Cost | B4: Quantity × Unit Cost | C4: Estimated cost of goods sold based on recorded unit cost.
A5: Estimated Contribution | B5: Net Sales − Product Cost − Delivery Cost | C5: Contribution after product and delivery costs only; not full accounting profit.
A6: Contribution Margin | B6: Estimated Contribution ÷ Net Sales | C6: Share of net sales remaining after included costs.
A7: Monthly Growth | B7: (Current month sales − previous month sales) ÷ previous month sales | C7: Measures month-on-month change; interpret seasonality carefully.
A8: Cleaning decision | B8: Exact duplicate Order IDs removed from Clean Data. | C8: Assumes Order ID uniquely identifies a line; real projects must confirm grain and ID design.
A9: Missing region | B9: Missing region values labeled 'Unknown'. | C9: Avoids silently guessing missing values; investigate source records if real data.
A10: Invalid quantity | B10: Quantity <= 0 flagged for review; not automatically corrected. | C10: Exclude or correct only after verifying the source. Current summaries retain it and therefore require analyst review.
A11: High discount | B11: Discount > 30% flagged for review. | C11: A flag indicates a potential anomaly, not proof of an error.
A12: Limitations | B12: Synthetic data; no overheads, returns, marketing, taxes, payment fees, inventory holding costs or customer acquisition costs. | C12: Do not generalize findings to a real company; validate all recommendations with actual data.
A13: Responsible interpretation | B13: Association is not causation. | C13: A relationship between discount and margin alone does not prove discounts caused a margin change.
